<?xml version="1.0"?>
<robot name="my_robot">

    <property name="pi" value="3.14" />

    <material name="green">
        <color rgba="0 0.75 0 1" />
    </material>
    <material name="blue">
        <color rgba="0 0 0.75 1" />
    </material>
    <material name="grey">
        <color rgba="0.5 0.5 0.5 1" />
    </material>
    <material name="yellow">
        <color rgba="1.0 0.93 0.7 1" />
    </material>    
    <material name="purple">
        <color rgba="0.4 0.23 0.72 1" />
    </material>    

    <link name="base_link">
        <visual>
            <geometry>
                <box size="0.6 0.4 0.2" />
            </geometry>
            <origin xyz="0 0 0.1" rpy="0 0 0" />
            <material name="blue" />
        </visual>
    </link>

    <link name="second_link">
        <visual>
            <geometry>
                <cylinder radius="0.1"  length="0.2" />
            </geometry>
            <origin xyz="0 0 0.1" rpy="0 0 0" />
            <material name="grey" />
        </visual>
    </link> 

    <link name="third_link">
        <visual>
            <geometry>
                <box size="0.05 0.05 0.05" />
            </geometry>
            <origin xyz="0 0 0.025" rpy="0 0 0" />
            <material name="purple" />
        </visual>
    </link>    

    <joint name = "base_second_joint" type = "revolute">
        <parent link = "base_link" />
        <child link = "second_link" />
        <origin xyz = "0 0 0.2" rpy = "0 0 0" />
        <axis xyz = "0 0 1" />
        <limit lower = "-${pi/2}" upper = "${pi/2}" velocity = "50" effort = "100" />
    </joint>

    <joint name = "second_third_joint" type = "prismatic" >
        <parent link = "second_link" />
        <child link = "third_link" />
        <origin xyz = "0 0 0.2" rpy = "0 0 0" />
        <axis xyz = "1 0 0" />
        <limit lower = "-0.1" upper = "0.1" velocity = "50" effort = "50" />
    </joint>

</robot>
